Workbook

Sheet Controle
A1: Data | B1: Mês | C1: Área | D1: Equipamento | E1: Relatório necessário? | F1: Responsável | G1: Atividade | H1: Programado | I1: Executado | J1: Diferença | K1: % Execução | L1: Status | M1: Observação | N1: Data Conclusão | O1: Motivo Desvio | P1: Relatório emitido?
A2: 46251 | B2: =IF(A2="","",PROPER(TEXT(A2,"mmmm"))) -> Agosto | C2: MARIMEX | E2: =IF(C2="","",IFERROR(VLOOKUP(C2,Clientes!$C$2:$D$1000,2,FALSE),"Não definido")) -> Não | F2: Galacho / Muller | G2: Manutenção preventiva de 1.500 horas | H2: 8 | I2: 8 | J2: =I2-H2 -> 0 | K2: =IF(H2="","",IFERROR(I2/H2,0)) -> 1 | L2: =IF(A73="","",IF(OR(I73="",I73=0),"Não executado",IF(K73>=1,"Concluído",IF(K73>=0.8,"Parcial","Não executado")))) -> Concluído
A3: 46251 | B3: =IF(A3="","",PROPER(TEXT(A3,"mmmm"))) -> Agosto | C3: TRANSBRASA | E3: =IF(C3="","",IFERROR(VLOOKUP(C3,Clientes!$C$2:$D$1000,2,FALSE),"Não definido")) -> Sim | F3: Davi / Danilson | G3: Manutenção preditiva de 750 horas | H3: 8 | I3: 8 | J3: =I3-H3 -> 0 | K3: =IF(H3="","",IFERROR(I3/H3,0)) -> 1 | L3: =IF(A3="","",IF(K3>=1,"Concluído",IF(K3>=0.8,"Parcial","Não executado"))) -> Concluído
A4: 46252 | B4: =IF(A4="","",PROPER(TEXT(A4,"mmmm"))) -> Agosto | C4: DINAMO ALEMOA | E4: =IF(C4="","",IFERROR(VLOOKUP(C4,Clientes!$C$2:$D$1000,2,FALSE),"Não definido")) -> Sim | F4: Gabriel / Muller | G4: Manutenção preventiva de 17.250 – Frota 03 | H4: 8 | I4: 8 | J4: =I4-H4 -> 0 | K4: =IF(H4="","",IFERROR(I4/H4,0)) -> 1 | L4: =IF(A4="","",IF(K4>=1,"Concluído",IF(K4>=0.8,"Parcial","Não executado"))) -> Concluído
A5: 46252 | B5: =IF(A5="","",PROPER(TEXT(A5,"mmmm"))) -> Agosto | C5: DELLA VOLPE | E5: =IF(C5="","",IFERROR(VLOOKUP(C5,Clientes!$C$2:$D$1000,2,FALSE),"Não definido")) -> Sim | F5: Davi / Leandro | G5: Manutenção preventiva de 10.000 horas | H5: 8 | I5: 8 | J5: =I5-H5 -> 0 | K5: =IF(H5="","",IFERROR(I5/H5,0)) -> 1 | L5: =IF(A5="","",IF(K5>=1,"Concluído",IF(K5>=0.8,"Parcial","Não executado"))) -> Concluído
A6: 46252 | B6: =IF(A6="","",PROPER(TEXT(A6,"mmmm"))) -> Agosto | C6: CGM LOGÍSTICA | E6: =IF(C6="","",IFERROR(VLOOKUP(C6,Clientes!$C$2:$D$1000,2,FALSE),"Não definido")) -> Sim | F6: joao / Danilson | G6: Manutenção preditiva de 3.750 horas | H6: 8 | I6: 8 | J6: =I6-H6 -> 0 | K6: =IF(H6="","",IFERROR(I6/H6,0)) -> 1 | L6: =IF(A6="","",IF(K6>=1,"Concluído",IF(K6>=0.8,"Parcial","Não executado"))) -> Concluído
A7: 46253 | B7: =IF(A7="","",PROPER(TEXT(A7,"mmmm"))) -> Agosto | C7: DINAMO ANCHIETA | E7: =IF(C7="","",IFERROR(VLOOKUP(C7,Clientes!$C$2:$D$1000,2,FALSE),"Não definido")) -> Sim | F7: Davi / Muller | G7: Inspeções de rotina | H7: 8 | I7: 8 | J7: =I7-H7 -> 0 | K7: =IF(H7="","",IFERROR(I7/H7,0)) -> 1 | L7: =IF(A7="","",IF(K7>=1,"Concluído",IF(K7>=0.8,"Parcial","Não executado"))) -> Concluído
A8: 46253 | B8: =IF(A8="","",PROPER(TEXT(A8,"mmmm"))) -> Agosto | C8: ISIS PÁTIO 01 | E8: =IF(C8="","",IFERROR(VLOOKUP(C8,Clientes!$C$2:$D$1000,2,FALSE),"Não definido")) -> Sim | F8: Galacho | G8: Montagem do motor QSM11 Frota 08 | H8: 8 | I8: 0 | J8: =I8-H8 -> -8 | K8: =IF(H8="","",IFERROR(I8/H8,0)) -> 0 | L8: =IF(A8="","",IF(K8>=1,"Concluído",IF(K8>=0.8,"Parcial","Não executado"))) -> Não executado | O8: Precisou levantar lança
A9: 46253 | B9: =IF(A9="","",PROPER(TEXT(A9,"mmmm"))) -> Agosto | C9: ISIS PÁTIO 02 | E9: =IF(C9="","",IFERROR(VLOOKUP(C9,Clientes!$C$2:$D$1000,2,FALSE),"Não definido")) -> Sim | F9: Carlos | G9: Avaliar a trinca da lança Frota 03, inspecionar na Porto Brasil o serviço do diferencial | H9: 8 | I9: 8 | J9: =I9-H9 -> 0 | K9: =IF(H9="","",IFERROR(I9/H9,0)) -> 1 | L9: =IF(A9="","",IF(K9>=1,"Concluído",IF(K9>=0.8,"Parcial","Não executado"))) -> Concluído
A10: 46253 | B10: =IF(A10="","",PROPER(TEXT(A10,"mmmm"))) -> Agosto | C10: EQUIPORT | E10: =IF(C10="","",IFERROR(VLOOKUP(C10,Clientes!$C$2:$D$1000,2,FALSE),"Não definido")) -> Não | F10: Pereira / Danilson | G10: Efetuar a reparação nos chicotes da transmissão e do chassi | H10: 8 | I10: 0 | J10: =I10-H10 -> -8 | K10: =IF(H10="","",IFERROR(I10/H10,0)) -> 0 | L10: =IF(A10="","",IF(K10>=1,"Concluído",IF(K10>=0.8,"Parcial","Não executado"))) -> Não executado | O10: Emergencia marimex
A11: 46253 | B11: =IF(A11="","",PROPER(TEXT(A11,"mmmm"))) -> Agosto | C11: EQUIPORT | E11: =IF(C11="","",IFERROR(VLOOKUP(C11,Clientes!$C$2:$D$1000,2,FALSE),"Não definido")) -> Não | F11: Leandro / Matheus | G11: Efetuar a limpeza dos aros de roda para fazer ensaios | H11: 8 | I11: 8 | J11: =I11-H11 -> 0 | K11: =IF(H11="","",IFERROR(I11/H11,0)) -> 1 | L11: =IF(A11="","",IF(K11>=1,"Concluído",IF(K11>=0.8,"Parcial","Não executado"))) -> Concluído
A12: 46253 | B12: =IF(A12="","",PROPER(TEXT(A12,"mmmm"))) -> Agosto | C12: EQUIPORT | E12: =IF(C12="","",IFERROR(VLOOKUP(C12,Clientes!$C$2:$D$1000,2,FALSE),"Não definido")) -> Não | F12: João Mauricio / Gabriel | G12: Sacar bucha danificada da lança móvel, avaliar mangueiras do chassi sem retirar, separação das peças do chassi e lança | H12: 8 | I12: 8 | J12: =I12-H12 -> 0 | K12: =IF(H12="","",IFERROR(I12/H12,0)) -> 1 | L12: =IF(A12="","",IF(K12>=1,"Concluído",IF(K12>=0.8,"Parcial","Não executado"))) -> Concluído | M12: Falta separação das peças do chassi e lança
A13: 46253 | B13: =IF(A13="","",PROPER(TEXT(A13,"mmmm"))) -> Agosto | C13: EQUIPORT | E13: =IF(C13="","",IFERROR(VLOOKUP(C13,Clientes!$C$2:$D$1000,2,FALSE),"Não definido")) -> Não | F13: Arthur | G13: Fazer lista de peças faltante e danificada | H13: 8 | I13: 8 | J13: =I13-H13 -> 0 | K13: =IF(H13="","",IFERROR(I13/H13,0)) -> 1 | L13: =IF(A13="","",IF(K13>=1,"Concluído",IF(K13>=0.8,"Parcial","Não executado"))) -> Concluído
A14: 46254 | B14: =IF(A14="","",PROPER(TEXT(A14,"mmmm"))) -> Agosto | C14: CRAGEA | E14: =IF(C14="","",IFERROR(VLOOKUP(C14,Clientes!$C$2:$D$1000,2,FALSE),"Não definido")) -> Sim | F14: Pereira / Muller | G14: Manutenção preventiva de 5.000 horas | H14: 8 | I14: 8 | J14: =I14-H14 -> 0 | K14: =IF(H14="","",IFERROR(I14/H14,0)) -> 1 | L14: =IF(A14="","",IF(K14>=1,"Concluído",IF(K14>=0.8,"Parcial","Não executado"))) -> Concluído
A15: 46254 | B15: =IF(A15="","",PROPER(TEXT(A15,"mmmm"))) -> Agosto | C15: TRANSBRASA | E15: =IF(C15="","",IFERROR(VLOOKUP(C15,Clientes!$C$2:$D$1000,2,FALSE),"Não definido")) -> Sim | F15: Davi / Leandro | G15: Manutenção preditiva de 1.250 horas KC1 | H15: 8 | I15: 8 | J15: =I15-H15 -> 0 | K15: =IF(H15="","",IFERROR(I15/H15,0)) -> 1 | L15: =IF(A15="","",IF(K15>=1,"Concluído",IF(K15>=0.8,"Parcial","Não executado"))) -> Concluído
A16: 46254 | B16: =IF(A16="","",PROPER(TEXT(A16,"mmmm"))) -> Agosto | C16: MARIMEX | E16: =IF(C16="","",IFERROR(VLOOKUP(C16,Clientes!$C$2:$D$1000,2,FALSE),"Não definido")) -> Não | F16: Gabriel / Danilson | G16: Manutenção preventiva de 150 horas E-404 | H16: 8 | I16: 8 | J16: =I16-H16 -> 0 | K16: =IF(H16="","",IFERROR(I16/H16,0)) -> 1 | L16: =IF(A16="","",IF(K16>=1,"Concluído",IF(K16>=0.8,"Parcial","Não executado"))) -> Concluído
A17: 46254 | B17: =IF(A17="","",PROPER(TEXT(A17,"mmmm"))) -> Agosto | C17: ISIS PÁTIO 01 | E17: =IF(C17="","",IFERROR(VLOOKUP(C17,Clientes!$C$2:$D$1000,2,FALSE),"Não definido")) -> Sim | F17: Galacho | G17: Montagem do motor QSM11 Frota 08 | H17: 8 | I17: 8 | J17: =I17-H17 -> 0 | K17: =IF(H17="","",IFERROR(I17/H17,0)) -> 1 | L17: =IF(A17="","",IF(K17>=1,"Concluído",IF(K17>=0.8,"Parcial","Não executado"))) -> Concluído | N17: 46255
A18: 46254 | B18: =IF(A18="","",PROPER(TEXT(A18,"mmmm"))) -> Agosto | C18: EQUIPORT | E18: =IF(C18="","",IFERROR(VLOOKUP(C18,Clientes!$C$2:$D$1000,2,FALSE),"Não definido")) -> Não | F18: Carlos / Matheus | G18: Alterar a posição que está calçado o equipamento EQP007 | H18: 8 | I18: 8 | J18: =I18-H18 -> 0 | K18: =IF(H18="","",IFERROR(I18/H18,0)) -> 1 | L18: =IF(A18="","",IF(K18>=1,"Concluído",IF(K18>=0.8,"Parcial","Não executado"))) -> Concluído
A19: 46254 | B19: =IF(A19="","",PROPER(TEXT(A19,"mmmm"))) -> Agosto | C19: EQUIPORT | E19: =IF(C19="","",IFERROR(VLOOKUP(C19,Clientes!$C$2:$D$1000,2,FALSE),"Não definido")) -> Não | F19: Arthur | G19: Fazer lista de peças faltante e danificada | H19: 8 | I19: 8 | J19: =I19-H19 -> 0 | K19: =IF(H19="","",IFERROR(I19/H19,0)) -> 1 | L19: =IF(A19="","",IF(K19>=1,"Concluído",IF(K19>=0.8,"Parcial","Não executado"))) -> Concluído
A20: 46255 | B20: =IF(A20="","",PROPER(TEXT(A20,"mmmm"))) -> Agosto | C20: ISIS PÁTIO 01 | E20: =IF(C20="","",IFERROR(VLOOKUP(C20,Clientes!$C$2:$D$1000,2,FALSE),"Não definido")) -> Sim | F20: Galacho | G20: Montagem do motor QSM11 Frota 08 | H20: 8 | I20: 8 | J20: =I20-H20 -> 0 | K20: =IF(H20="","",IFERROR(I20/H20,0)) -> 1 | L20: =IF(A20="","",IF(K20>=1,"Concluído",IF(K20>=0.8,"Parcial","Não executado"))) -> Concluído
A21: 46255 | B21: =IF(A21="","",PROPER(TEXT(A21,"mmmm"))) -> Agosto | C21: TRANSBRASA | E21: =IF(C21="","",IFERROR(VLOOKUP(C21,Clientes!$C$2:$D$1000,2,FALSE),"Não definido")) -> Sim | F21: Davi / Leandro | G21: Manutenção preditiva de 1.250 horas – KC3 | H21: 8 | I21: 8 | J21: =I21-H21 -> 0 | K21: =IF(H21="","",IFERROR(I21/H21,0)) -> 1 | L21: =IF(A21="","",IF(K21>=1,"Concluído",IF(K21>=0.8,"Parcial","Não executado"))) -> Concluído
A22: 46255 | B22: =IF(A22="","",PROPER(TEXT(A22,"mmmm"))) -> Agosto | C22: MARIMEX | E22: =IF(C22="","",IFERROR(VLOOKUP(C22,Clientes!$C$2:$D$1000,2,FALSE),"Não definido")) -> Não | F22: Gabriel / Danilson | G22: Manutenção preventiva de 150 horas – E-405 | H22: 8 | I22: 8 | J22: =I22-H22 -> 0 | K22: =IF(H22="","",IFERROR(I22/H22,0)) -> 1 | L22: =IF(A22="","",IF(K22>=1,"Concluído",IF(K22>=0.8,"Parcial","Não executado"))) -> Concluído
A23: 46255 | B23: =IF(A23="","",PROPER(TEXT(A23,"mmmm"))) -> Agosto | C23: EQUIPORT | E23: =IF(C23="","",IFERROR(VLOOKUP(C23,Clientes!$C$2:$D$1000,2,FALSE),"Não definido")) -> Não | F23: Carlos | G23: Analisar o mecanismo do anti-tombamento, se houver necessidade já substituir | H23: 8 | I23: 8 | J23: =I23-H23 -> 0 | K23: =IF(H23="","",IFERROR(I23/H23,0)) -> 1 | L23: =IF(A23="","",IF(K23>=1,"Concluído",IF(K23>=0.8,"Parcial","Não executado"))) -> Concluído | O23: Atendimento Transtec
A24: 46255 | B24: =IF(A24="","",PROPER(TEXT(A24,"mmmm"))) -> Agosto | C24: EQUIPORT | E24: =IF(C24="","",IFERROR(VLOOKUP(C24,Clientes!$C$2:$D$1000,2,FALSE),"Não definido")) -> Não | F24: João Mauricio | G24: Verificar escapamento danificado, reparar com as peças compradas e algumas peças que veio da Granport | H24: 8 | I24: 8 | J24: =I24-H24 -> 0 | K24: =IF(H24="","",IFERROR(I24/H24,0)) -> 1 | L24: =IF(A24="","",IF(K24>=1,"Concluído",IF(K24>=0.8,"Parcial","Não executado"))) -> Concluído
A25: 46255 | B25: =IF(A25="","",PROPER(TEXT(A25,"mmmm"))) -> Agosto | C25: EQUIPORT | E25: =IF(C25="","",IFERROR(VLOOKUP(C25,Clientes!$C$2:$D$1000,2,FALSE),"Não definido")) -> Não | F25: Arthur / Matheus | G25: Fixação dos tubos e calhas do chassi | H25: 8 | I25: 0 | J25: =I25-H25 -> -8 | K25: =IF(H25="","",IFERROR(I25/H25,0)) -> 0 | L25: =IF(A25="","",IF(K25>=1,"Concluído",IF(K25>=0.8,"Parcial","Não executado"))) -> Não executado | M25: Realizado a remoção das rotulas do link e limpeza. | O25: Falta abraçadeiras, parafusos e porca
A26: 46255 | B26: =IF(A26="","",PROPER(TEXT(A26,"mmmm"))) -> Agosto | C26: EQUIPORT | E26: =IF(C26="","",IFERROR(VLOOKUP(C26,Clientes!$C$2:$D$1000,2,FALSE),"Não definido")) -> Não | F26: Pereira / Muller | G26: Dar continuação nos serviços de reparação nos chicotes da transmissão e do chassi, revisão da chave geral e contatora | H26: 8 | I26: 8 | J26: =I26-H26 -> 0 | K26: =IF(H26="","",IFERROR(I26/H26,0)) -> 1 | L26: =IF(A26="","",IF(K26>=1,"Concluído",IF(K26>=0.8,"Parcial","Não executado"))) -> Concluído
A27: 46256 | B27: =IF(A27="","",PROPER(TEXT(A27,"mmmm"))) -> Agosto | C27: ISIS PÁTIO 01 | E27: =IF(C27="","",IFERROR(VLOOKUP(C27,Clientes!$C$2:$D$1000,2,FALSE),"Não definido")) -> Sim | F27: Galacho | G27: Montagem do motor QSM11 Frota 08 | H27: 8 | I27: 8 | J27: =I27-H27 -> 0 | K27: =IF(H27="","",IFERROR(I27/H27,0)) -> 1 | L27: =IF(A27="","",IF(K27>=1,"Concluído",IF(K27>=0.8,"Parcial","Atrasado"))) -> Concluído
A28: 46256 | B28: =IF(A28="","",PROPER(TEXT(A28,"mmmm"))) -> Agosto | C28: DP WORLD | E28: =IF(C28="","",IFERROR(VLOOKUP(C28,Clientes!$C$2:$D$1000,2,FALSE),"Não definido")) -> Não | F28: Davi / Leandro | G28: Inspeções e lavagens dos equipamentos | H28: 8 | I28: 8 | J28: =I28-H28 -> 0 | K28: =IF(H28="","",IFERROR(I28/H28,0)) -> 1 | L28: =IF(A28="","",IF(K28>=1,"Concluído",IF(K28>=0.8,"Parcial","Atrasado"))) -> Concluído
A29: 46257 | B29: =IF(A29="","",PROPER(TEXT(A29,"mmmm"))) -> Agosto | C29: LSL TRANSPORTES | E29: =IF(C29="","",IFERROR(VLOOKUP(C29,Clientes!$C$2:$D$1000,2,FALSE),"Não definido")) -> Sim | F29: Galacho | G29: Limpeza do tanque ARLA | H29: 8 | I29: 8 | J29: =I29-H29 -> 0 | K29: =IF(H29="","",IFERROR(I29/H29,0)) -> 1 | L29: =IF(A29="","",IF(K29>=1,"Concluído",IF(K29>=0.8,"Parcial","Atrasado"))) -> Concluído
A30: 46258 | B30: =IF(A30="","",PROPER(TEXT(A30,"mmmm"))) -> Agosto | C30: ISIS PÁTIO 01 | E30: =IF(C30="","",IFERROR(VLOOKUP(C30,Clientes!$C$2:$D$1000,2,FALSE),"Não definido")) -> Sim | F30: Galacho | G30: Montagem do motor QSM11 Frota 08 | H30: 8 | I30: 0 | J30: =I30-H30 -> -8 | K30: =IF(H30="","",IFERROR(I30/H30,0)) -> 0 | L30: =IF(A30="","",IF(K30>=1,"Concluído",IF(K30>=0.8,"Parcial","Não executado"))) -> Não executado | O30: Falta de material (parafusos )
A31: 46258 | B31: =IF(A31="","",PROPER(TEXT(A31,"mmmm"))) -> Agosto | C31: EQUIPORT | E31: =IF(C31="","",IFERROR(VLOOKUP(C31,Clientes!$C$2:$D$1000,2,FALSE),"Não definido")) -> Não | F31: Arthur / Gabriel | G31: Continuação, fixação dos tubos e calhas do chassi, substituição das rótulas dos links de direção, analisar o mecanismo do anti-tombamento, se houver necessidade já substituir | H31: 8 | I31: 0 | J31: =I31-H31 -> -8 | K31: =IF(H31="","",IFERROR(I31/H31,0)) -> 0 | L31: =IF(A31="","",IF(K31>=1,"Concluído",IF(K31>=0.8,"Parcial","Não executado"))) -> Não executado | O31: Link não bate as especificação tecnica.
A32: 46258 | B32: =IF(A32="","",PROPER(TEXT(A32,"mmmm"))) -> Agosto | C32: EQUIPORT | E32: =IF(C32="","",IFERROR(VLOOKUP(C32,Clientes!$C$2:$D$1000,2,FALSE),"Não definido")) -> Não | F32: João Mauricio / Danilson | G32: Continuação, reparar escapamento danificado | H32: 8 | I32: 8 | J32: =I32-H32 -> 0 | K32: =IF(H32="","",IFERROR(I32/H32,0)) -> 1 | L32: =IF(A32="","",IF(K32>=1,"Concluído",IF(K32>=0.8,"Parcial","Não executado"))) -> Concluído
A33: 46258 | B33: =IF(A33="","",PROPER(TEXT(A33,"mmmm"))) -> Agosto | C33: EQUIPORT | E33: =IF(C33="","",IFERROR(VLOOKUP(C33,Clientes!$C$2:$D$1000,2,FALSE),"Não definido")) -> Não | F33: Carlos | G33: Verificar junto com o Flavio os serviços a serem realizados nessa semana na EQP007 | H33: 8 | I33: 8 | J33: =I33-H33 -> 0 | K33: =IF(H33="","",IFERROR(I33/H33,0)) -> 1 | L33: =IF(A33="","",IF(K33>=1,"Concluído",IF(K33>=0.8,"Parcial","Não executado"))) -> Concluído
A34: 46259 | B34: =IF(A34="","",PROPER(TEXT(A34,"mmmm"))) -> Agosto | C34: CESARI | E34: =IF(C34="","",IFERROR(VLOOKUP(C34,Clientes!$C$2:$D$1000,2,FALSE),"Não definido")) -> Não | F34: Leandro | G34: Manutenção preventiva de 500 horas Empilhadeira Elétrica KONECRANES | H34: 8 | I34: 8 | J34: =I34-H34 -> 0 | K34: =IF(H34="","",IFERROR(I34/H34,0)) -> 1 | L34: =IF(A34="","",IF(K34>=1,"Concluído",IF(K34>=0.8,"Parcial","Não executado"))) -> Concluído
A35: 46259 | B35: =IF(A35="","",PROPER(TEXT(A35,"mmmm"))) -> Agosto | C35: MOVECTA ITAJÁI | E35: =IF(C35="","",IFERROR(VLOOKUP(C35,Clientes!$C$2:$D$1000,2,FALSE),"Não definido")) -> Sim | F35: Pereira | G35: (Manutenção preventiva de 1.500 horas | H35: 8 | I35: 8 | J35: =I35-H35 -> 0 | K35: =IF(H35="","",IFERROR(I35/H35,0)) -> 1 | L35: =IF(A35="","",IF(K35>=1,"Concluído",IF(K35>=0.8,"Parcial","Não executado"))) -> Concluído
A36: 46259 | B36: =IF(A36="","",PROPER(TEXT(A36,"mmmm"))) -> Agosto | C36: S. MAGALHÃES | E36: =IF(C36="","",IFERROR(VLOOKUP(C36,Clientes!$C$2:$D$1000,2,FALSE),"Não definido")) -> Sim | F36: Carlos | G36: Verificar as pressões hidráulica – problema na bomba hidráulica | H36: 8 | I36: 8 | J36: =I36-H36 -> 0 | K36: =IF(H36="","",IFERROR(I36/H36,0)) -> 1 | L36: =IF(A36="","",IF(K36>=1,"Concluído",IF(K36>=0.8,"Parcial","Não executado"))) -> Concluído
A37: 46259 | B37: =IF(A37="","",PROPER(TEXT(A37,"mmmm"))) -> Agosto | C37: DINAMO ANCHIETA | E37: =IF(C37="","",IFERROR(VLOOKUP(C37,Clientes!$C$2:$D$1000,2,FALSE),"Não definido")) -> Sim | F37: Arthur / Galacho | G37: Substituir o cilindro de telescopagem Frota 02 | H37: 8 | I37: 8 | J37: =I37-H37 -> 0 | K37: =IF(H37="","",IFERROR(I37/H37,0)) -> 1 | L37: =IF(A37="","",IF(K37>=1,"Concluído",IF(K37>=0.8,"Parcial","Não executado"))) -> Concluído
A38: 46259 | B38: =IF(A38="","",PROPER(TEXT(A38,"mmmm"))) -> Agosto | C38: TRANSBRASA | E38: =IF(C38="","",IFERROR(VLOOKUP(C38,Clientes!$C$2:$D$1000,2,FALSE),"Não definido")) -> Sim | F38: Davi / Muller | G38: Inspeções de rotina nas 03 máquinas | H38: 4 | I38: 4 | J38: =I38-H38 -> 0 | K38: =IF(H38="","",IFERROR(I38/H38,0)) -> 1 | L38: =IF(A38="","",IF(K38>=1,"Concluído",IF(K38>=0.8,"Parcial","Não executado"))) -> Concluído
A39: 46259 | B39: =IF(A39="","",PROPER(TEXT(A39,"mmmm"))) -> Agosto | C39: DINAMO ALEMOA | E39: =IF(C39="","",IFERROR(VLOOKUP(C39,Clientes!$C$2:$D$1000,2,FALSE),"Não definido")) -> Sim | F39: Davi / Muller | G39: Instalar peças aprovadas – tampa do tanque de expansão e sensor de 0 a 25 bar da transmissão | H39: 4 | I39: 4 | J39: =I39-H39 -> 0 | K39: =IF(H39="","",IFERROR(I39/H39,0)) -> 1 | L39: =IF(A39="","",IF(K39>=1,"Concluído",IF(K39>=0.8,"Parcial","Não executado"))) -> Concluído
A40: 46259 | B40: =IF(A40="","",PROPER(TEXT(A40,"mmmm"))) -> Agosto | C40: EQUIPORT | E40: =IF(C40="","",IFERROR(VLOOKUP(C40,Clientes!$C$2:$D$1000,2,FALSE),"Não definido")) -> Não | F40: Décio / João Mauricio | G40: Continuação, reparar escapamento danificado, com as peças compradas e algumas peças que veio da Granpor | H40: 8 | I40: 8 | J40: =I40-H40 -> 0 | K40: =IF(H40="","",IFERROR(I40/H40,0)) -> 1 | L40: =IF(A40="","",IF(K40>=1,"Concluído",IF(K40>=0.8,"Parcial","Não executado"))) -> Concluído
...

Sheet Clientes
C1: Área | D1: Relatório necessário?
C2: CGM LOGÍSTICA | D2: Sim
C3: DELLA VOLPE | D3: Sim
C4: DINAMO ANCHIETA | D4: Sim
C5: DINAMO ALEMOA | D5: Sim
C6: EDI AURORA | D6: Sim
C7: EQUIPORT | D7: Não
C8: ISIS PÁTIO 01 | D8: Sim
C9: ISIS PÁTIO 02 | D9: Sim
C10: LSL TRANSPORTES | D10: Sim
C11: TERRA MASTER | D11: Sim
C12: ADUKARGO | D12: Sim
... C38: NELCAR | D38: Sim

Sheet Dashboard
A1: Aderência à Programação
A2: Consolidado do período registrado | Fonte: aba Controle
A4: Horas programadas | D4: Horas executadas | G4: Aderência | J4: Horas pendentes
A5: =SUM(Controle!$H$2:$H$500000) -> 840 | D5: =SUM(Controle!$I$2:$I$500000) -> 768 | G5: =IFERROR(D5/A5,0) -> 0.91428571 | J5: =A5-D5 -> 72
A9: Indicador | B9: Horas | D9: Status | E9: Atividades
A10: Programadas | B10: =A5 -> 840 | D10: Concluídas | E10: =COUNTIF(Controle!$L$2:$L$87,"Concluído") -> 78
A11: Executadas | B11: =D5 -> 768 | D11: Não executadas | E11: =COUNTIF(Controle!$L$2:$L$87,"Não executado") -> 8
A12: Pendentes | B12: =J5 -> 72 | D12: Sem status | E12: =COUNTBLANK(Controle!$L$2:$L$87) -> 0
D13: Total | E13: =COUNTA(Controle!$A$2:$A$87) -> 86
A16: Área | B16: Horas pendentes | D16: Leitura gerencial
A17: EQUIPORT | B17: =SUMIFS(Controle!$H$2:$H$87,Controle!$C$2:$C$87,"EQUIPORT")-SUMIFS(Controle!$I$2:$I$87,Controle!$C$2:$C$87,"EQUIPORT") -> 40 | D17: A aderência é calculada em horas programadas.
A18: ISIS PÁTIO 01 | B18: =SUM(Controle!$H$8,Controle!$H$30)-SUM(Controle!$I$8,Controle!$I$30) -> 16 | D18: ="Pendência concentrada: "&TEXT(B20/A5,"0%")&" das horas programadas." -> Pendência concentrada: 8% das horas programadas.
A19: TRANSTEC | B19: =SUMIFS(Controle!$H$2:$H$87,Controle!$C$2:$C$87,"TRANSTEC")-SUMIFS(Controle!$I$2:$I$87,Controle!$C$2:$C$87,"TRANSTEC") -> 8 | D19: ="Registros sem status: "&E12 -> Registros sem status: 0
A20: Total | B20: =SUM(B17:B19) -> 64
